Workbook

Sheet csv
A1: ID_OS;TAG;Equipamento;Setor;Tipo;Data_Abertura;Prazo;Data_Conclusao;Status;Responsavel;Prioridade
A2: OS-001;CMP-002;Compressor de ar 2;Utilidades;Preventiva;2026-07-22;2026-08-21;2026-08-27;Concluída;Ana Souza;Alta
A3: OS-002;ARC-001;Ar-condicionado central;Predial;Preventiva;2026-07-22;2026-08-21;2026-08-19;Concluída;Rafael Costa;Média
A4: OS-003;TRN-001;Torno CNC;Produção;Preventiva;2026-07-24;2026-08-23;2026-08-18;Concluída;Paula Mendes;Média
A5: OS-004;TRN-001;Torno CNC;Produção;Preventiva;2026-07-25;2026-08-14;2026-08-11;Concluída;Ana Souza;Média
A6: OS-005;BMB-002;Bomba centrífuga 2;Utilidades;Preventiva;2026-07-28;2026-08-12;2026-08-07;Concluída;Paula Mendes;Média
A7: OS-006;BMB-001;Bomba centrífuga 1;Utilidades;Preventiva;2026-08-05;2026-08-20;2026-08-20;Concluída;Ana Souza;Alta
A8: OS-007;PRS-001;Prensa hidráulica;Produção;Preventiva;2026-08-05;2026-08-25;2026-08-20;Concluída;Paula Mendes;Alta
A9: OS-008;GER-001;Gerador diesel;Elétrica;Preventiva;2026-08-06;2026-08-13;2026-08-11;Concluída;Rafael Costa;Baixa
A10: OS-009;TRF-001;Transformador 500 kVA;Elétrica;Preventiva;2026-08-07;2026-08-17;2026-08-16;Concluída;Ana Souza;Baixa
A11: OS-010;TRN-001;Torno CNC;Produção;Preventiva;2026-08-08;2026-08-15;2026-08-12;Concluída;Paula Mendes;Média
A12: OS-011;QDF-002;Quadro de distribuição B;Elétrica;Preventiva;2026-08-08;2026-08-15;2026-08-21;Concluída;Paula Mendes;Média
... A101: OS-100;TRF-001;Transformador 500 kVA;Elétrica;Preventiva;2026-11-01;2026-11-08;;Aberta;Ana Souza;Média

Sheet ordens_de_servico
A1: ID_OS | B1: TAG | C1: Equipamento | D1: Setor | E1: Tipo | F1: Data_Abertura | G1: Prazo | H1: Data_Conclusão | I1: Status | J1: Responsável | K1: Prioridade
A2: OS-001 | B2: CMP-002 | C2: Compressor de ar 2 | D2: Utilidades | E2: Preventiva | F2: 46225 | G2: 46255 | H2: 46261 | I2: Concluída | J2: Ana Souza | K2: Alta
A3: OS-002 | B3: ARC-001 | C3: Ar-condicionado central | D3: Predial | E3: Preventiva | F3: 46225 | G3: 46255 | H3: 46253 | I3: Concluída | J3: Rafael Costa | K3: Média
A4: OS-003 | B4: TRN-001 | C4: Torno CNC | D4: Produção | E4: Preventiva | F4: 46227 | G4: 46257 | H4: 46252 | I4: Concluída | J4: Paula Mendes | K4: Média
A5: OS-004 | B5: TRN-001 | C5: Torno CNC | D5: Produção | E5: Preventiva | F5: 46228 | G5: 46248 | H5: 46245 | I5: Concluída | J5: Ana Souza | K5: Média
A6: OS-005 | B6: BMB-002 | C6: Bomba centrífuga 2 | D6: Utilidades | E6: Preventiva | F6: 46231 | G6: 46246 | H6: 46241 | I6: Concluída | J6: Paula Mendes | K6: Média
A7: OS-006 | B7: BMB-001 | C7: Bomba centrífuga 1 | D7: Utilidades | E7: Preventiva | F7: 46239 | G7: 46254 | H7: 46254 | I7: Concluída | J7: Ana Souza | K7: Alta
A8: OS-007 | B8: PRS-001 | C8: Prensa hidráulica | D8: Produção | E8: Preventiva | F8: 46239 | G8: 46259 | H8: 46254 | I8: Concluída | J8: Paula Mendes | K8: Alta
A9: OS-008 | B9: GER-001 | C9: Gerador diesel | D9: Elétrica | E9: Preventiva | F9: 46240 | G9: 46247 | H9: 46245 | I9: Concluída | J9: Rafael Costa | K9: Baixa
A10: OS-009 | B10: TRF-001 | C10: Transformador 500 kVA | D10: Elétrica | E10: Preventiva | F10: 46241 | G10: 46251 | H10: 46250 | I10: Concluída | J10: Ana Souza | K10: Baixa
A11: OS-010 | B11: TRN-001 | C11: Torno CNC | D11: Produção | E11: Preventiva | F11: 46242 | G11: 46249 | H11: 46246 | I11: Concluída | J11: Paula Mendes | K11: Média
A12: OS-011 | B12: QDF-002 | C12: Quadro de distribuição B | D12: Elétrica | E12: Preventiva | F12: 46242 | G12: 46249 | H12: 46255 | I12: Concluída | J12: Paula Mendes | K12: Média
A13: OS-012 | B13: ELV-001 | C13: Elevador de carga | D13: Predial | E13: Preventiva | F13: 46244 | G13: 46254 | H13: 46252 | I13: Concluída | J13: Marcos Pereira | K13: Média
... A22: OS-021 | B22: CMP-002 | C22: Compressor de ar 2 | D22: Utilidades | E22: Preventiva | F22: 46254 | G22: 46261 | H22: 46270 | I22: Concluída | J22: Juliana Alves | K22: Média
A23: OS-022 | B23: ARC-001 | C23: Ar-condicionado central | D23: Predial | E23: Preventiva | F23: 46254 | G23: 46274 | I23: Em andamento | J23: Paula Mendes | K23: Baixa
A24: OS-023 | B24: BCI-001 | C24: Bomba de incêndio | D24: Predial | E24: Preventiva | F24: 46256 | G24: 46276 | H24: 46275 | I24: Concluída | J24: Rafael Costa | K24: Baixa
A25: OS-024 | B25: CMP-002 | C25: Compressor de ar 2 | D25: Utilidades | E25: Preventiva | F25: 46256 | G25: 46276 | H25: 46265 | I25: Concluída | J25: Marcos Pereira | K25: Baixa
A26: OS-025 | B26: ELV-002 | C26: Elevador social | D26: Predial | E26: Preventiva | F26: 46257 | G26: 46267 | H26: 46263 | I26: Concluída | J26: Marcos Pereira | K26: Baixa
A27: OS-026 | B27: ARC-002 | C27: Ar-condicionado split sala 2 | D27: Predial | E27: Preventiva | F27: 46258 | G27: 46278 | H27: 46259 | I27: Concluída | J27: Ana Souza | K27: Média
A28: OS-027 | B28: BMB-001 | C28: Bomba centrífuga 1 | D28: Utilidades | E28: Preventiva | F28: 46258 | G28: 46288 | H28: 46288 | I28: Concluída | J28: Juliana Alves | K28: Média
A29: OS-028 | B29: ARC-001 | C29: Ar-condicionado central | D29: Predial | E29: Preventiva | F29: 46262 | G29: 46282 | I29: Em andamento | J29: Paula Mendes | K29: Média
A30: OS-029 | B30: QDF-002 | C30: Quadro de distribuição B | D30: Elétrica | E30: Preventiva | F30: 46262 | G30: 46269 | H30: 46263 | I30: Concluída | J30: Paula Mendes | K30: Baixa
A31: OS-030 | B31: ARC-002 | C31: Ar-condicionado split sala 2 | D31: Predial | E31: Preventiva | F31: 46264 | G31: 46271 | I31: Em andamento | J31: Paula Mendes | K31: Média
A32: OS-031 | B32: TRF-001 | C32: Transformador 500 kVA | D32: Elétrica | E32: Preventiva | F32: 46264 | G32: 46284 | H32: 46279 | I32: Concluída | J32: Paula Mendes | K32: Média
A33: OS-032 | B33: BCI-001 | C33: Bomba de incêndio | D33: Predial | E33: Preventiva | F33: 46265 | G33: 46272 | I33: Em andamento | J33: Carlos Lima | K33: Média
A34: OS-033 | B34: BMB-002 | C34: Bomba centrífuga 2 | D34: Utilidades | E34: Preventiva | F34: 46265 | G34: 46275 | H34: 46277 | I34: Concluída | J34: Paula Mendes | K34: Baixa
A35: OS-034 | B35: ARC-002 | C35: Ar-condicionado split sala 2 | D35: Predial | E35: Preventiva | F35: 46266 | G35: 46276 | I35: Aberta | J35: Marcos Pereira | K35: Média
A36: OS-035 | B36: ARC-002 | C36: Ar-condicionado split sala 2 | D36: Predial | E36: Preventiva | F36: 46266 | G36: 46276 | I36: Aberta | J36: Rafael Costa | K36: Alta
A37: OS-036 | B37: TRN-001 | C37: Torno CNC | D37: Produção | E37: Preventiva | F37: 46267 | G37: 46282 | H37: 46277 | I37: Concluída | J37: Ana Souza | K37: Alta
A38: OS-037 | B38: CDR-001 | C38: Caldeira a vapor | D38: Utilidades | E38: Preventiva | F38: 46267 | G38: 46287 | I38: Aberta | J38: Paula Mendes | K38: Alta
A39: OS-038 | B39: ARC-001 | C39: Ar-condicionado central | D39: Predial | E39: Preventiva | F39: 46268 | G39: 46288 | H39: 46371 | I39: Concluída | J39: Carlos Lima | K39: Média
A40: OS-039 | B40: CMP-002 | C40: Compressor de ar 2 | D40: Utilidades | E40: Preventiva | F40: 46273 | G40: 46283 | H40: 46330 | I40: Concluída | J40: Juliana Alves | K40: Alta
A41: OS-040 | B41: ARC-002 | C41: Ar-condicionado split sala 2 | D41: Predial | E41: Preventiva | F41: 46273 | G41: 46303 | I41: Aberta | J41: Paula Mendes | K41: Baixa
A42: OS-041 | B42: ESP-001 | C42: Esteira transportadora | D42: Produção | E42: Preventiva | F42: 46273 | G42: 46283 | H42: 46282 | I42: Concluída | J42: Rafael Costa | K42: Baixa
A43: OS-042 | B43: BMB-001 | C43: Bomba centrífuga 1 | D43: Utilidades | E43: Preventiva | F43: 46273 | G43: 46283 | H43: 46286 | I43: Concluída | J43: Carlos Lima | K43: Média
A44: OS-043 | B44: PRS-001 | C44: Prensa hidráulica | D44: Produção | E44: Preventiva | F44: 46274 | G44: 46281 | I44: Aberta | J44: Rafael Costa | K44: Média
A45: OS-044 | B45: BCI-001 | C45: Bomba de incêndio | D45: Predial | E45: Preventiva | F45: 46274 | G45: 46304 | I45: Aberta | J45: Juliana Alves | K45: Baixa
A46: OS-045 | B46: CDR-001 | C46: Caldeira a vapor | D46: Utilidades | E46: Preventiva | F46: 46274 | G46: 46304 | I46: Aberta | J46: Juliana Alves | K46: Média
A47: OS-046 | B47: QDF-001 | C47: Quadro de distribuição A | D47: Elétrica | E47: Preventiva | F47: 46274 | G47: 46304 | I47: Aberta | J47: Marcos Pereira | K47: Baixa
A48: OS-047 | B48: EXA-001 | C48: Exaustor industrial | D48: Produção | E48: Preventiva | F48: 46274 | G48: 46304 | I48: Em andamento | J48: Juliana Alves | K48: Média
...

Sheet resumo
AP1: =TODAY() -> 46304
C5: Responsável | D5: Geral
C7: STATUS DAS OS GERAL / RESPONSÁVEL | F7: ID_OS | G7: Equipamento | H7: Prazo | I7: Desvio_de_Prazo | J7: Status
C8: Aberta | D8: =IF($D$5="Geral",COUNTIF(ordens_de_servico!I:I,resumo!C8),COUNTIFS(ordens_de_servico!J:J,resumo!$D$5,ordens_de_servico!I:I,resumo!C8)) -> 45 | F8: OS-001 | G8: Compressor de ar 2 | H8: 46255 | I8: =IF(ordens_de_servico!H2>ordens_de_servico!G2,-DATEDIF(ordens_de_servico!G2,ordens_de_servico!H2,"d"),IF(ordens_de_servico!H2=0,"",DATEDIF(ordens_de_servico!H2,ordens_de_servico!G2,"d"))) -> -6 | J8: =IF($D$5=ordens_de_servico!J2,ordens_de_servico!I2,"")
C9: Em andamento | D9: =IF($D$5="Geral",COUNTIF(ordens_de_servico!I:I,resumo!C9),COUNTIFS(ordens_de_servico!J:J,resumo!$D$5,ordens_de_servico!I:I,resumo!C9)) -> 21 | F9: OS-002 | G9: Ar-condicionado central | H9: 46255 | I9: =IF(ordens_de_servico!H3>ordens_de_servico!G3,-DATEDIF(ordens_de_servico!G3,ordens_de_servico!H3,"d"),IF(ordens_de_servico!H3=0,"",DATEDIF(ordens_de_servico!H3,ordens_de_servico!G3,"d"))) -> 2 | J9: =IF($D$5=ordens_de_servico!J3,ordens_de_servico!I3,"")
C10: Concluída | D10: =IF($D$5="Geral",COUNTIF(ordens_de_servico!I:I,resumo!C10),COUNTIFS(ordens_de_servico!J:J,resumo!$D$5,ordens_de_servico!I:I,resumo!C10)) -> 34 | F10: OS-003 | G10: Torno CNC | H10: 46257 | I10: =IF(ordens_de_servico!H4>ordens_de_servico!G4,-DATEDIF(ordens_de_servico!G4,ordens_de_servico!H4,"d"),IF(ordens_de_servico!H4=0,"",DATEDIF(ordens_de_servico!H4,ordens_de_servico!G4,"d"))) -> 5 | J10: =IF($D$5=ordens_de_servico!J4,ordens_de_servico!I4,"")
C11: Total | D11: =SUM(D8:D10) -> 100 | F11: OS-004 | G11: Torno CNC | H11: 46248 | I11: =IF(ordens_de_servico!H5>ordens_de_servico!G5,-DATEDIF(ordens_de_servico!G5,ordens_de_servico!H5,"d"),IF(ordens_de_servico!H5=0,"",DATEDIF(ordens_de_servico!H5,ordens_de_servico!G5,"d"))) -> 3 | J11: =IF($D$5=ordens_de_servico!J5,ordens_de_servico!I5,"")
F12: OS-005 | G12: Bomba centrífuga 2 | H12: 46246 | I12: =IF(ordens_de_servico!H6>ordens_de_servico!G6,-DATEDIF(ordens_de_servico!G6,ordens_de_servico!H6,"d"),IF(ordens_de_servico!H6=0,"",DATEDIF(ordens_de_servico!H6,ordens_de_servico!G6,"d"))) -> 5 | J12: =IF($D$5=ordens_de_servico!J6,ordens_de_servico!I6,"")
F13: OS-006 | G13: Bomba centrífuga 1 | H13: 46254 | I13: =IF(ordens_de_servico!H7>ordens_de_servico!G7,-DATEDIF(ordens_de_servico!G7,ordens_de_servico!H7,"d"),IF(ordens_de_servico!H7=0,"",DATEDIF(ordens_de_servico!H7,ordens_de_servico!G7,"d"))) -> 0 | J13: =IF($D$5=ordens_de_servico!J7,ordens_de_servico!I7,"")
F14: OS-007 | G14: Prensa hidráulica | H14: 46259 | I14: =IF(ordens_de_servico!H8>ordens_de_servico!G8,-DATEDIF(ordens_de_servico!G8,ordens_de_servico!H8,"d"),IF(ordens_de_servico!H8=0,"",DATEDIF(ordens_de_servico!H8,ordens_de_servico!G8,"d"))) -> 5 | J14: =IF($D$5=ordens_de_servico!J8,ordens_de_servico!I8,"")
F15: OS-008 | G15: Gerador diesel | H15: 46247 | I15: =IF(ordens_de_servico!H9>ordens_de_servico!G9,-DATEDIF(ordens_de_servico!G9,ordens_de_servico!H9,"d"),IF(ordens_de_servico!H9=0,"",DATEDIF(ordens_de_servico!H9,ordens_de_servico!G9,"d"))) -> 2 | J15: =IF($D$5=ordens_de_servico!J9,ordens_de_servico!I9,"")
F16: OS-009 | G16: Transformador 500 kVA | H16: 46251 | I16: =IF(ordens_de_servico!H10>ordens_de_servico!G10,-DATEDIF(ordens_de_servico!G10,ordens_de_servico!H10,"d"),IF(ordens_de_servico!H10=0,"",DATEDIF(ordens_de_servico!H10,ordens_de_servico!G10,"d"))) -> 1 | J16: =IF($D$5=ordens_de_servico!J10,ordens_de_servico!I10,"")
F17: OS-010 | G17: Torno CNC | H17: 46249 | I17: =IF(ordens_de_servico!H11>ordens_de_servico!G11,-DATEDIF(ordens_de_servico!G11,ordens_de_servico!H11,"d"),IF(ordens_de_servico!H11=0,"",DATEDIF(ordens_de_servico!H11,ordens_de_servico!G11,"d"))) -> 3 | J17: =IF($D$5=ordens_de_servico!J11,ordens_de_servico!I11,"")
F18: OS-011 | G18: Quadro de distribuição B | H18: 46249 | I18: =IF(ordens_de_servico!H12>ordens_de_servico!G12,-DATEDIF(ordens_de_servico!G12,ordens_de_servico!H12,"d"),IF(ordens_de_servico!H12=0,"",DATEDIF(ordens_de_servico!H12,ordens_de_servico!G12,"d"))) -> -6 | J18: =IF($D$5=ordens_de_servico!J12,ordens_de_servico!I12,"")
F19: OS-012 | G19: Elevador de carga | H19: 46254 | I19: =IF(ordens_de_servico!H13>ordens_de_servico!G13,-DATEDIF(ordens_de_servico!G13,ordens_de_servico!H13,"d"),IF(ordens_de_servico!H13=0,"",DATEDIF(ordens_de_servico!H13,ordens_de_servico!G13,"d"))) -> 2 | J19: =IF($D$5=ordens_de_servico!J13,ordens_de_servico!I13,"")
F20: OS-013 | G20: Bomba dosadora | H20: 46265 | I20: =IF(ordens_de_servico!H14>ordens_de_servico!G14,-DATEDIF(ordens_de_servico!G14,ordens_de_servico!H14,"d"),IF(ordens_de_servico!H14=0,"",DATEDIF(ordens_de_servico!H14,ordens_de_servico!G14,"d"))) -> 4 | J20: =IF($D$5=ordens_de_servico!J14,ordens_de_servico!I14,"")
F21: OS-014 | G21: Torno CNC | H21: 46266 | I21: =IF(ordens_de_servico!H15>ordens_de_servico!G15,-DATEDIF(ordens_de_servico!G15,ordens_de_servico!H15,"d"),IF(ordens_de_servico!H15=0,"",DATEDIF(ordens_de_servico!H15,ordens_de_servico!G15,"d"))) -> 4 | J21: =IF($D$5=ordens_de_servico!J15,ordens_de_servico!I15,"")
F22: OS-015 | G22: Caldeira a vapor | H22: 46256 | I22: =IF(ordens_de_servico!H16>ordens_de_servico!G16,-DATEDIF(ordens_de_servico!G16,ordens_de_servico!H16,"d"),IF(ordens_de_servico!H16=0,"",DATEDIF(ordens_de_servico!H16,ordens_de_servico!G16,"d"))) -> 3 | J22: =IF($D$5=ordens_de_servico!J16,ordens_de_servico!I16,"")
F23: OS-016 | G23: Ar-condicionado split sala 2 | H23: 46280 | I23: =IF(ordens_de_servico!H17>ordens_de_servico!G17,-DATEDIF(ordens_de_servico!G17,ordens_de_servico!H17,"d"),IF(ordens_de_servico!H17=0,"",DATEDIF(ordens_de_servico!H17,ordens_de_servico!G17,"d"))) -> 0 | J23: =IF($D$5=ordens_de_servico!J17,ordens_de_servico!I17,"")
... F107: OS-100 | G107: Transformador 500 kVA | H107: 46334 | I107: =IF(ordens_de_servico!H101>ordens_de_servico!G101,-DATEDIF(ordens_de_servico!G101,ordens_de_servico!H101,"d"),IF(ordens_de_servico!H101=0,"",DATEDIF(ordens_de_servico!H101,ordens_de_servico!G101,"d"))) | J107: =IF($D$5=ordens_de_servico!J101,ordens_de_servico!I101,"")
